2013-03-01 20:07:49,803 - ERROR - stderr - Traceback (most recent call last): (/Users/garetjax/Projects/subcommands/subcommands/logging.py:87)
2013-03-01 20:07:49,804 - ERROR - stderr -   File "/Users/garetjax/.virtualenvs/simple-cloud/bin/scloud", line 8, in <module> (/Users/garetjax/Projects/subcommands/subcommands/logging.py:87)
2013-03-01 20:07:49,804 - ERROR - stderr -     load_entry_point('simple-cloud==0.1a', 'console_scripts', 'scloud')() (/Users/garetjax/Projects/subcommands/subcommands/logging.py:87)
2013-03-01 20:07:49,804 - ERROR - stderr -   File "/Users/garetjax/Projects/subcommands/subcommands/main.py", line 65, in _main (/Users/garetjax/Projects/subcommands/subcommands/logging.py:87)
2013-03-01 20:07:49,804 - ERROR - stderr -     sys.exit(main(name, package, sys.argv[1:])) (/Users/garetjax/Projects/subcommands/subcommands/logging.py:87)
2013-03-01 20:07:49,804 - ERROR - stderr -   File "/Users/garetjax/Projects/subcommands/subcommands/main.py", line 53, in main (/Users/garetjax/Projects/subcommands/subcommands/logging.py:87)
2013-03-01 20:07:49,804 - ERROR - stderr -     res = args.command.execute(args) (/Users/garetjax/Projects/subcommands/subcommands/logging.py:87)
2013-03-01 20:07:49,804 - ERROR - stderr -   File "/Users/garetjax/Projects/simple-cloud/simplecloud/commands/list_servers.py", line 156, in execute (/Users/garetjax/Projects/subcommands/subcommands/logging.py:87)
2013-03-01 20:07:49,805 - ERROR - stderr -     self.handle(args.cmd, id) (/Users/garetjax/Projects/subcommands/subcommands/logging.py:87)
2013-03-01 20:07:49,805 - ERROR - stderr -   File "/Users/garetjax/Projects/simple-cloud/simplecloud/commands/list_servers.py", line 152, in handle (/Users/garetjax/Projects/subcommands/subcommands/logging.py:87)
2013-03-01 20:07:49,805 - ERROR - stderr -     cmd(uuid) (/Users/garetjax/Projects/subcommands/subcommands/logging.py:87)
2013-03-01 20:07:49,805 - ERROR - stderr -   File "/Users/garetjax/Projects/simple-cloud/simplecloud/commands/list_servers.py", line 111, in handle_POWEROFF (/Users/garetjax/Projects/subcommands/subcommands/logging.py:87)
2013-03-01 20:07:49,805 - ERROR - stderr -     subprocess.check_call(cmd) (/Users/garetjax/Projects/subcommands/subcommands/logging.py:87)
2013-03-01 20:07:49,805 - ERROR - stderr -   File "/usr/local/Cellar/python/2.7.3/Frameworks/Python.framework/Versions/2.7/lib/python2.7/subprocess.py", line 511, in check_call (/Users/garetjax/Projects/subcommands/subcommands/logging.py:87)
2013-03-01 20:07:49,805 - ERROR - stderr -     raise CalledProcessError(retcode, cmd) (/Users/garetjax/Projects/subcommands/subcommands/logging.py:87)
2013-03-01 20:07:49,805 - ERROR - stderr - subprocess.CalledProcessError: Command '['VBoxManage', '--nologo', 'controlvm', 'd8854522-1558-4e09-be4e-ecbdd468be9c', 'poweroff']' returned non-zero exit status 1 (/Users/garetjax/Projects/subcommands/subcommands/logging.py:87)
